Workbook

Sheet 新聞稿資料庫
A1: 國教行動聯盟 2023-2025 新聞稿資料庫
A2: 資料來源：原始新聞稿 ｜ 去重後共 116 篇 ｜ 建表日期：2026/03/06
A4: 編號 | B4: 年度 | C4: 日期 | D4: 標題 | E4: 議題分類 | F4: 次要議題 | G4: 行動類型 | H4: 訴求對象 | I4: 政府回應 | J4: 檔案名
A5: 1 | B5: 2023 | C5: 2023/00/00 | D5: 記者會新聞稿 | E5: 其他 | G5: 記者會 | J5: 記者會新聞稿.docx
A6: 2 | B6: 2023 | C6: 2023/00/00 | D6: 林為洲新聞稿 | E6: 其他 | G6: 新聞稿 | J6: 林為洲新聞稿 .docx
A7: 3 | B7: 2023 | C7: 2023/00/00 | D7: 「預防性騷擾從小開始」記者會新聞稿 | E7: 青少年性健康 | G7: 記者會 | J7: 「預防性騷擾從小開始」記者會新聞稿.docx
A8: 4 | B8: 2023 | C8: 2023/00/00 | D8: 「增加申請入學穩定度，彰顯『得所應得』的公義價值」新聞稿 | E8: 教育政策 | G8: 新聞稿 | J8: 「增加申請入學穩定度，彰顯『得所應得』的公義價值」新聞稿.docx
A9: 5 | B9: 2023 | C9: 2023/00/00 | D9: 政府匆促預告指定菸品健康風險評估辦法 民團強烈要求：避免未 | E9: 菸害防制 | G9: 新聞稿 | J9: [2.21台灣拒菸聯盟 新聞稿]政府匆促預告指定菸品健康風險評估辦法 民團強烈要求：避免未.docx
A10: 6 | B10: 2023 | C10: 2023/00/00 | D10: 菸害防制新法民眾疑問大解惑 聯盟呼籲中央政府確實支持縣市衛 | E10: 菸害防制 | G10: 新聞稿 | J10: [3.17台灣拒菸聯盟新聞稿]菸害防制新法民眾疑問大解惑 聯盟呼籲中央政府確實支持縣市衛.docx
A11: 7 | B11: 2023 | C11: 2023/00/00 | D11: 2024023國教行動聯盟新聞稿「有效預防即時輔導降低霸凌傷害 國教盟與中山大學攜手防制 | E11: 校園安全 | F11: 心理健康 | G11: 新聞稿 | J11: 2024023國教行動聯盟新聞稿「有效預防即時輔導降低霸凌傷害 國教盟與中山大學攜手防制.docx
A12: 8 | B12: 2023 | C12: 2023/01/04 | D12: 新聞稿-會後 | E12: 其他 | G12: 新聞稿 | J12: 20230104新聞稿-會後.docx
A13: 9 | B13: 2023 | C13: 2023/01/04 | D13: 全長聯新聞稿-草稿（文昌修） | E13: 其他 | G13: 新聞稿 | J13: 20230104全長聯新聞稿-草稿（文昌修）.docx
A14: 10 | B14: 2023 | C14: 2023/01/09 | D14: 全長聯新聞稿-草稿（文昌修） | E14: 其他 | G14: 新聞稿 | J14: 20230109全長聯新聞稿-草稿（文昌修）.docx
A15: 11 | B15: 2023 | C15: 2023/01/10 | D15: 「110拒絕菸品載具廣告 搶救下一代 」新聞稿ok | E15: 菸害防制 | G15: 新聞稿 | J15: 20230110「110拒絕菸品載具廣告 搶救下一代 」新聞稿ok.docx
A16: 12 | B16: 2023 | C16: 2023/01/12 | D16: [112.1.12全國家長會長聯盟-台灣拒菸聯盟新聞稿] | E16: 菸害防制 | G16: 新聞稿 | J16: [112.1.12全國家長會長聯盟-台灣拒菸聯盟新聞稿].docx
A17: 13 | B17: 2023 | C17: 2023/01/12 | D17: 新聞稿 | E17: 菸害防制 | G17: 新聞稿 | J17: 112.1.12[全國家長會長聯盟-台灣拒菸聯盟]新聞稿.docx
A18: 14 | B18: 2023 | C18: 2023/01/12 | D18: 修 | E18: 菸害防制 | G18: 新聞稿 | J18: [112.1.12全國家長會長聯盟-台灣拒菸聯盟新聞稿]修.docx
A19: 15 | B19: 2023 | C19: 2023/02/17 | D19: 新聞稿-草稿1 | E19: 菸害防制 | G19: 新聞稿 | J19: 2.17新聞稿-草稿1.docx
A20: 16 | B20: 2023 | C20: 2023/03/02 | D20: 新聞稿-草稿-6 | E20: 菸害防制 | G20: 新聞稿 | J20: 3.2新聞稿-草稿-6.docx
A21: 17 | B21: 2023 | C21: 2023/03/07 | D21: 台灣拒菸聯盟新聞稿符合世界潮流 台灣大專校院全面禁菸ok | E21: 菸害防制 | G21: 新聞稿 | J21: 3.7台灣拒菸聯盟新聞稿符合世界潮流 台灣大專校院全面禁菸ok.docx
A22: 18 | B22: 2023 | C22: 2023/03/25 | D22: 加味菸預告新聞稿OK(1) | E22: 菸害防制 | G22: 新聞稿 | J22: 3.25加味菸預告新聞稿OK(1).docx
A23: 19 | B23: 2023 | C23: 2023/03/27 | D23: 人本教育基金會新聞稿_請政府堅定支援父母，終止暴力複製 | E23: 其他 | G23: 新聞稿 | J23: 20230327人本教育基金會新聞稿_請政府堅定支援父母，終止暴力複製.docx
... A26: 22 | B26: 2023 | C26: 2023/05/04 | D26: 新聞稿草稿 | E26: 菸害防制 | G26: 新聞稿 | J26: 5.4新聞稿草稿.docx
A27: 23 | B27: 2023 | C27: 2023/05/11 | D27: 國教行動聯盟新聞稿「有效預防即時輔導降低霸凌傷害 國教盟與橄欖枝中心攜手防 | E27: 校園安全 | F27: 心理健康 | G27: 新聞稿 | J27: 20230511國教行動聯盟新聞稿「有效預防即時輔導降低霸凌傷害 國教盟與橄欖枝中心攜手防.docx
A28: 24 | B28: 2023 | C28: 2023/05/22 | D28: 台灣拒菸聯盟 新聞稿-草稿 | E28: 菸害防制 | G28: 新聞稿 | J28: 20230522台灣拒菸聯盟 新聞稿-草稿.docx
A29: 25 | B29: 2023 | C29: 2023/05/29 | D29: 新聞稿 | E29: 菸害防制 | G29: 記者會 | J29: 5.29新聞稿.docx
A30: 26 | B30: 2023 | C30: 2023/06/14 | D30: 新聞稿-草4 | E30: 菸害防制 | G30: 新聞稿 | J30: 6.14新聞稿-草4.docx
A31: 27 | B31: 2023 | C31: 2023/06/14 | D31: 新聞稿-台灣拒菸聯盟致函縣市長 力推「高中職以下學校周邊50公尺內拒售加熱菸」 | E31: 菸害防制 | G31: 新聞稿 | J31: 6.14新聞稿-台灣拒菸聯盟致函縣市長 力推「高中職以下學校周邊50公尺內拒售加熱菸」.docx
A32: 28 | B32: 2023 | C32: 2023/06/20 | D32: 國教行動聯盟新聞稿「國教盟呼籲家長信任幼教人員」 | E32: 教育政策 | G32: 新聞稿 | J32: 20230620國教行動聯盟新聞稿「國教盟呼籲家長信任幼教人員」.docx
A33: 29 | B33: 2023 | C33: 2023/06/30 | D33: 國教行動聯盟新聞稿「給他魚吃不如教他釣魚 提升學生競爭力應優先於學費補貼」 | E33: 教育政策 | G33: 新聞稿 | J33: 20230630國教行動聯盟新聞稿「給他魚吃不如教他釣魚 提升學生競爭力應優先於學費補貼」.docx
A34: 30 | B34: 2023 | C34: 2023/07/04 | D34: 國教行動聯盟「支持合理管教，拒絕暴力發飆」新聞稿 | E34: 兒少保護 | G34: 新聞稿 | J34: 20230704：國教行動聯盟「支持合理管教，拒絕暴力發飆」新聞稿.docx
A35: 31 | B35: 2023 | C35: 2023/07/04 | D35: 新聞稿：國教行動聯盟_台灣共善促進協會【正視大麻趨勢與危害，研商保護青少年 | E35: 大麻防制 | G35: 新聞稿 | J35: 20230704新聞稿：國教行動聯盟_台灣共善促進協會【正視大麻趨勢與危害，研商保護青少年.docx
A36: 32 | B36: 2023 | C36: 2023/07/29 | D36: 國教行動聯盟對「性別平等教育法」三讀通過的回應 | E36: 其他 | G36: 新聞稿 | J36: 20230729國教行動聯盟對「性別平等教育法」三讀通過的回應.docx
A37: 33 | B37: 2023 | C37: 2023/08/21 | D37: 國教行動聯盟新聞稿「有效預防即時輔導降低霸凌傷害 國教盟與橄欖枝中心攜手防 | E37: 校園安全 | F37: 心理健康 | G37: 新聞稿 | J37: 20230821國教行動聯盟新聞稿「有效預防即時輔導降低霸凌傷害 國教盟與橄欖枝中心攜手防.docx
A38: 34 | B38: 2023 | C38: 2023/08/31 | D38: 新聞稿：霸凌防制修法配套不足 預防及輔導才是重點 | E38: 校園安全 | F38: 心理健康 | G38: 新聞稿 | J38: 20230831新聞稿：霸凌防制修法配套不足 預防及輔導才是重點.docx
A39: 35 | B39: 2023 | C39: 2023/09/05 | D39: 記者會新聞稿 | E39: 其他 | G39: 記者會 | J39: 9.5記者會新聞稿.docx
A40: 36 | B40: 2023 | C40: 2023/09/06 | D40: 新聞稿 | E40: 其他 | G40: 新聞稿 | J40: 9.6新聞稿.docx
A41: 37 | B41: 2023 | C41: 2023/09/06 | D41: 國教行動聯盟新聞稿「加熱菸審查欠缺嚴格把關與本土研究 青少年將成受害最大族 | E41: 菸害防制 | G41: 新聞稿 | J41: 20230906國教行動聯盟新聞稿「加熱菸審查欠缺嚴格把關與本土研究 青少年將成受害最大族.docx
A42: 38 | B42: 2023 | C42: 2023/09/22 | D42: 台灣拒菸聯盟新聞稿 | E42: 菸害防制 | G42: 新聞稿 | J42: 112.9.22台灣拒菸聯盟新聞稿.docx
A43: 39 | B43: 2023 | C43: 2023/09/25 | D43: 國教行動聯盟新聞稿「國教盟呼籲共同致力師生關係」 | E43: 教育政策 | G43: 新聞稿 | J43: 20230925國教行動聯盟新聞稿「國教盟呼籲共同致力師生關係」.docx
...

Sheet 議題追蹤總覽
A1: 國教行動聯盟 議題追蹤總覽（2023-2025）
A2: 自動統計 ｜ 黃底欄位為手動填寫
A4: 議題 | B4: 2023年 | C4: 2024年 | D4: 2025年 | E4: 總計 | F4: 記者會/公聽會 | G4: 有政府回應 | H4: 倡議現況 | I4: 下一步行動
A5: 菸害防制 | B5: =COUNTIFS(新聞稿資料庫!E5:E120,A5,新聞稿資料庫!B5:B120,"2023") -> 18 | C5: =COUNTIFS(新聞稿資料庫!E5:E120,A5,新聞稿資料庫!B5:B120,"2024") -> 0 | D5: =COUNTIFS(新聞稿資料庫!E5:E120,A5,新聞稿資料庫!B5:B120,"2025") -> 18 | E5: =SUM(B5:D5) -> 36 | F5: =COUNTIFS(新聞稿資料庫!E5:E120,A5,新聞稿資料庫!G5:G120,"<>新聞稿") -> 4 | G5: =COUNTIFS(新聞稿資料庫!E5:E120,A5,新聞稿資料庫!I5:I120,"有") -> 1
A6: 校園安全 | B6: =COUNTIFS(新聞稿資料庫!E5:E120,A6,新聞稿資料庫!B5:B120,"2023") -> 6 | C6: =COUNTIFS(新聞稿資料庫!E5:E120,A6,新聞稿資料庫!B5:B120,"2024") -> 13 | D6: =COUNTIFS(新聞稿資料庫!E5:E120,A6,新聞稿資料庫!B5:B120,"2025") -> 8 | E6: =SUM(B6:D6) -> 27 | F6: =COUNTIFS(新聞稿資料庫!E5:E120,A6,新聞稿資料庫!G5:G120,"<>新聞稿") -> 7 | G6: =COUNTIFS(新聞稿資料庫!E5:E120,A6,新聞稿資料庫!I5:I120,"有") -> 1
A7: 青少年性健康 | B7: =COUNTIFS(新聞稿資料庫!E5:E120,A7,新聞稿資料庫!B5:B120,"2023") -> 1 | C7: =COUNTIFS(新聞稿資料庫!E5:E120,A7,新聞稿資料庫!B5:B120,"2024") -> 0 | D7: =COUNTIFS(新聞稿資料庫!E5:E120,A7,新聞稿資料庫!B5:B120,"2025") -> 11 | E7: =SUM(B7:D7) -> 12 | F7: =COUNTIFS(新聞稿資料庫!E5:E120,A7,新聞稿資料庫!G5:G120,"<>新聞稿") -> 4 | G7: =COUNTIFS(新聞稿資料庫!E5:E120,A7,新聞稿資料庫!I5:I120,"有") -> 1
A8: 兒少保護 | B8: =COUNTIFS(新聞稿資料庫!E5:E120,A8,新聞稿資料庫!B5:B120,"2023") -> 2 | C8: =COUNTIFS(新聞稿資料庫!E5:E120,A8,新聞稿資料庫!B5:B120,"2024") -> 0 | D8: =COUNTIFS(新聞稿資料庫!E5:E120,A8,新聞稿資料庫!B5:B120,"2025") -> 6 | E8: =SUM(B8:D8) -> 8 | F8: =COUNTIFS(新聞稿資料庫!E5:E120,A8,新聞稿資料庫!G5:G120,"<>新聞稿") -> 4 | G8: =COUNTIFS(新聞稿資料庫!E5:E120,A8,新聞稿資料庫!I5:I120,"有") -> 3
A9: 教育政策 | B9: =COUNTIFS(新聞稿資料庫!E5:E120,A9,新聞稿資料庫!B5:B120,"2023") -> 5 | C9: =COUNTIFS(新聞稿資料庫!E5:E120,A9,新聞稿資料庫!B5:B120,"2024") -> 0 | D9: =COUNTIFS(新聞稿資料庫!E5:E120,A9,新聞稿資料庫!B5:B120,"2025") -> 4 | E9: =SUM(B9:D9) -> 9 | F9: =COUNTIFS(新聞稿資料庫!E5:E120,A9,新聞稿資料庫!G5:G120,"<>新聞稿") -> 1 | G9: =COUNTIFS(新聞稿資料庫!E5:E120,A9,新聞稿資料庫!I5:I120,"有") -> 3
A10: 心理健康 | B10: =COUNTIFS(新聞稿資料庫!E5:E120,A10,新聞稿資料庫!B5:B120,"2023") -> 0 | C10: =COUNTIFS(新聞稿資料庫!E5:E120,A10,新聞稿資料庫!B5:B120,"2024") -> 0 | D10: =COUNTIFS(新聞稿資料庫!E5:E120,A10,新聞稿資料庫!B5:B120,"2025") -> 6 | E10: =SUM(B10:D10) -> 6 | F10: =COUNTIFS(新聞稿資料庫!E5:E120,A10,新聞稿資料庫!G5:G120,"<>新聞稿") -> 1 | G10: =COUNTIFS(新聞稿資料庫!E5:E120,A10,新聞稿資料庫!I5:I120,"有") -> 1
A11: 青年參與 | B11: =COUNTIFS(新聞稿資料庫!E5:E120,A11,新聞稿資料庫!B5:B120,"2023") -> 0 | C11: =COUNTIFS(新聞稿資料庫!E5:E120,A11,新聞稿資料庫!B5:B120,"2024") -> 0 | D11: =COUNTIFS(新聞稿資料庫!E5:E120,A11,新聞稿資料庫!B5:B120,"2025") -> 3 | E11: =SUM(B11:D11) -> 3 | F11: =COUNTIFS(新聞稿資料庫!E5:E120,A11,新聞稿資料庫!G5:G120,"<>新聞稿") -> 1 | G11: =COUNTIFS(新聞稿資料庫!E5:E120,A11,新聞稿資料庫!I5:I120,"有") -> 0
A12: 大麻防制 | B12: =COUNTIFS(新聞稿資料庫!E5:E120,A12,新聞稿資料庫!B5:B120,"2023") -> 1 | C12: =COUNTIFS(新聞稿資料庫!E5:E120,A12,新聞稿資料庫!B5:B120,"2024") -> 0 | D12: =COUNTIFS(新聞稿資料庫!E5:E120,A12,新聞稿資料庫!B5:B120,"2025") -> 0 | E12: =SUM(B12:D12) -> 1 | F12: =COUNTIFS(新聞稿資料庫!E5:E120,A12,新聞稿資料庫!G5:G120,"<>新聞稿") -> 0 | G12: =COUNTIFS(新聞稿資料庫!E5:E120,A12,新聞稿資料庫!I5:I120,"有") -> 0
A13: 人工生殖 | B13: =COUNTIFS(新聞稿資料庫!E5:E120,A13,新聞稿資料庫!B5:B120,"2023") -> 0 | C13: =COUNTIFS(新聞稿資料庫!E5:E120,A13,新聞稿資料庫!B5:B120,"2024") -> 0 | D13: =COUNTIFS(新聞稿資料庫!E5:E120,A13,新聞稿資料庫!B5:B120,"2025") -> 1 | E13: =SUM(B13:D13) -> 1 | F13: =COUNTIFS(新聞稿資料庫!E5:E120,A13,新聞稿資料庫!G5:G120,"<>新聞稿") -> 0 | G13: =COUNTIFS(新聞稿資料庫!E5:E120,A13,新聞稿資料庫!I5:I120,"有") -> 0
A14: 早期療育 | B14: =COUNTIFS(新聞稿資料庫!E5:E120,A14,新聞稿資料庫!B5:B120,"2023") -> 0 | C14: =COUNTIFS(新聞稿資料庫!E5:E120,A14,新聞稿資料庫!B5:B120,"2024") -> 0 | D14: =COUNTIFS(新聞稿資料庫!E5:E120,A14,新聞稿資料庫!B5:B120,"2025") -> 1 | E14: =SUM(B14:D14) -> 1 | F14: =COUNTIFS(新聞稿資料庫!E5:E120,A14,新聞稿資料庫!G5:G120,"<>新聞稿") -> 0 | G14: =COUNTIFS(新聞稿資料庫!E5:E120,A14,新聞稿資料庫!I5:I120,"有") -> 0
A15: 其他 | B15: =COUNTIFS(新聞稿資料庫!E5:E120,A15,新聞稿資料庫!B5:B120,"2023") -> 11 | C15: =COUNTIFS(新聞稿資料庫!E5:E120,A15,新聞稿資料庫!B5:B120,"2024") -> 0 | D15: =COUNTIFS(新聞稿資料庫!E5:E120,A15,新聞稿資料庫!B5:B120,"2025") -> 1 | E15: =SUM(B15:D15) -> 12 | F15: =COUNTIFS(新聞稿資料庫!E5:E120,A15,新聞稿資料庫!G5:G120,"<>新聞稿") -> 2 | G15: =COUNTIFS(新聞稿資料庫!E5:E120,A15,新聞稿資料庫!I5:I120,"有") -> 0
A16: 合計 | B16: =SUM(B5:B15) -> 44 | C16: =SUM(C5:C15) -> 13 | D16: =SUM(D5:D15) -> 59 | E16: =SUM(E5:E15) -> 116 | F16: =SUM(F5:F15) -> 24 | G16: =SUM(G5:G15) -> 10

Sheet 年度月度統計
A1: 年度月度倡議統計（2023-2025）
A3: 月份 | B3: 2023年 | C3: 2024年 | D3: 2025年 | E3: 合計
A4: 01月 | B4: =COUNTIFS(新聞稿資料庫!B5:B120,"2023",新聞稿資料庫!C5:C120,"2023/01/*") -> 7 | C4: =COUNTIFS(新聞稿資料庫!B5:B120,"2024",新聞稿資料庫!C5:C120,"2024/01/*") -> 2 | D4: =COUNTIFS(新聞稿資料庫!B5:B120,"2025",新聞稿資料庫!C5:C120,"2025/01/*") -> 11 | E4: =SUM(B4:D4) -> 20
A5: 02月 | B5: =COUNTIFS(新聞稿資料庫!B5:B120,"2023",新聞稿資料庫!C5:C120,"2023/02/*") -> 1 | C5: =COUNTIFS(新聞稿資料庫!B5:B120,"2024",新聞稿資料庫!C5:C120,"2024/02/*") -> 0 | D5: =COUNTIFS(新聞稿資料庫!B5:B120,"2025",新聞稿資料庫!C5:C120,"2025/02/*") -> 2 | E5: =SUM(B5:D5) -> 3
A6: 03月 | B6: =COUNTIFS(新聞稿資料庫!B5:B120,"2023",新聞稿資料庫!C5:C120,"2023/03/*") -> 5 | C6: =COUNTIFS(新聞稿資料庫!B5:B120,"2024",新聞稿資料庫!C5:C120,"2024/03/*") -> 1 | D6: =COUNTIFS(新聞稿資料庫!B5:B120,"2025",新聞稿資料庫!C5:C120,"2025/03/*") -> 5 | E6: =SUM(B6:D6) -> 11
A7: 04月 | B7: =COUNTIFS(新聞稿資料庫!B5:B120,"2023",新聞稿資料庫!C5:C120,"2023/04/*") -> 0 | C7: =COUNTIFS(新聞稿資料庫!B5:B120,"2024",新聞稿資料庫!C5:C120,"2024/04/*") -> 2 | D7: =COUNTIFS(新聞稿資料庫!B5:B120,"2025",新聞稿資料庫!C5:C120,"2025/04/*") -> 4 | E7: =SUM(B7:D7) -> 6
A8: 05月 | B8: =COUNTIFS(新聞稿資料庫!B5:B120,"2023",新聞稿資料庫!C5:C120,"2023/05/*") -> 5 | C8: =COUNTIFS(新聞稿資料庫!B5:B120,"2024",新聞稿資料庫!C5:C120,"2024/05/*") -> 0 | D8: =COUNTIFS(新聞稿資料庫!B5:B120,"2025",新聞稿資料庫!C5:C120,"2025/05/*") -> 4 | E8: =SUM(B8:D8) -> 9
A9: 06月 | B9: =COUNTIFS(新聞稿資料庫!B5:B120,"2023",新聞稿資料庫!C5:C120,"2023/06/*") -> 4 | C9: =COUNTIFS(新聞稿資料庫!B5:B120,"2024",新聞稿資料庫!C5:C120,"2024/06/*") -> 0 | D9: =COUNTIFS(新聞稿資料庫!B5:B120,"2025",新聞稿資料庫!C5:C120,"2025/06/*") -> 4 | E9: =SUM(B9:D9) -> 8
A10: 07月 | B10: =COUNTIFS(新聞稿資料庫!B5:B120,"2023",新聞稿資料庫!C5:C120,"2023/07/*") -> 3 | C10: =COUNTIFS(新聞稿資料庫!B5:B120,"2024",新聞稿資料庫!C5:C120,"2024/07/*") -> 1 | D10: =COUNTIFS(新聞稿資料庫!B5:B120,"2025",新聞稿資料庫!C5:C120,"2025/07/*") -> 3 | E10: =SUM(B10:D10) -> 7
A11: 08月 | B11: =COUNTIFS(新聞稿資料庫!B5:B120,"2023",新聞稿資料庫!C5:C120,"2023/08/*") -> 2 | C11: =COUNTIFS(新聞稿資料庫!B5:B120,"2024",新聞稿資料庫!C5:C120,"2024/08/*") -> 2 | D11: =COUNTIFS(新聞稿資料庫!B5:B120,"2025",新聞稿資料庫!C5:C120,"2025/08/*") -> 4 | E11: =SUM(B11:D11) -> 8
A12: 09月 | B12: =COUNTIFS(新聞稿資料庫!B5:B120,"2023",新聞稿資料庫!C5:C120,"2023/09/*") -> 5 | C12: =COUNTIFS(新聞稿資料庫!B5:B120,"2024",新聞稿資料庫!C5:C120,"2024/09/*") -> 2 | D12: =COUNTIFS(新聞稿資料庫!B5:B120,"2025",新聞稿資料庫!C5:C120,"2025/09/*") -> 2 | E12: =SUM(B12:D12) -> 9
A13: 10月 | B13: =COUNTIFS(新聞稿資料庫!B5:B120,"2023",新聞稿資料庫!C5:C120,"2023/10/*") -> 0 | C13: =COUNTIFS(新聞稿資料庫!B5:B120,"2024",新聞稿資料庫!C5:C120,"2024/10/*") -> 0 | D13: =COUNTIFS(新聞稿資料庫!B5:B120,"2025",新聞稿資料庫!C5:C120,"2025/10/*") -> 7 | E13: =SUM(B13:D13) -> 7
A14: 11月 | B14: =COUNTIFS(新聞稿資料庫!B5:B120,"2023",新聞稿資料庫!C5:C120,"2023/11/*") -> 0 | C14: =COUNTIFS(新聞稿資料庫!B5:B120,"2024",新聞稿資料庫!C5:C120,"2024/11/*") -> 1 | D14: =COUNTIFS(新聞稿資料庫!B5:B120,"2025",新聞稿資料庫!C5:C120,"2025/11/*") -> 6 | E14: =SUM(B14:D14) -> 7
A15: 12月 | B15: =COUNTIFS(新聞稿資料庫!B5:B120,"2023",新聞稿資料庫!C5:C120,"2023/12/*") -> 5 | C15: =COUNTIFS(新聞稿資料庫!B5:B120,"2024",新聞稿資料庫!C5:C120,"2024/12/*") -> 0 | D15: =COUNTIFS(新聞稿資料庫!B5:B120,"2025",新聞稿資料庫!C5:C120,"2025/12/*") -> 7 | E15: =SUM(B15:D15) -> 12
A16: 合計 | B16: =SUM(B4:B15) -> 37 | C16: =SUM(C4:C15) -> 11 | D16: =SUM(D4:D15) -> 59 | E16: =SUM(E4:E15) -> 107
