Workbook

Sheet 新聞稿資料庫
A1: 編號 | B1: 年度 | C1: 日期 | D1: 標題 | E1: 議題分類 | F1: 次要議題 | G1: 行動類型 | H1: 訴求對象 | I1: 政府回應 | J1: 新聞露出 | K1: 連結
A2: 1 | B2: 2023 | C2: 2023/03/29 | D2: 七成家長反對刪除懲戒權 管教不是暴力 家長不是兇手 捍衛家長合理管教權 反對缺乏配套的粗暴修法 | E2: 兒少保護 | G2: 新聞稿 | I2: 有 | J2: 新聞露出8篇 | K2: 20230329【國教行動聯盟新聞稿
A3: 2 | B3: 2023 | C3: 2023/05/11 | D3: 有效預防即時輔導降低霸凌傷害 國教盟與橄欖枝中心攜手防制霸凌 | E3: 校園安全 | G3: 新聞稿 | J3: 無 | K3: 20230511【國教行動聯盟新聞稿】
A4: 3 | B4: 2023 | C4: 2023/06/20 | D4: 教保人員辛苦了！ 國教盟呼籲家長信任幼教人員 勿因噎廢食、因小失大 | E4: 其他 | G4: 新聞稿 | J4: 新聞露出2篇 | K4: 20230620【國教行動聯盟新聞稿】
A5: 4 | B5: 2023 | C5: 2023/06/28 | D5: 有效預防 即時輔導 降低霸凌傷害 國教盟與高雄中山大學攜手防制校園霸凌 | E5: 校園安全 | G5: 新聞稿 | J5: 無 | K5: 20230628【國教行動聯盟新聞稿】
A6: 5 | B6: 2023 | C6: 2023/06/30 | D6: 給他魚吃，不如教他釣魚 提升學生競爭力應優先於學費補貼 教育經費運用應有更精緻化考量 | E6: 其他 | G6: 新聞稿 | J6: 新聞露出4篇 | K6: 20230630【國教行動聯盟新聞稿】
A7: 6 | B7: 2023 | C7: 2023/07/03 | D7: 支持合理管教，拒絕暴力發飆 國教盟呼籲重視家庭教育、家長也應學習求助 | E7: 其他 | G7: 新聞稿 | I7: 有 | J7: 新聞露出2篇 | K7: 20230703【國教行動聯盟新聞稿】
A8: 7 | B8: 2023 | C8: 2023/07/04 | D8: 【正視大麻趨勢與危害，研商保護青少年對策】 台灣第一次大麻防制論壇！ 青少年大麻防制刻不容緩！ 「2023臺灣青少年大麻防制因應對策論壇」 | E8: 大麻防制 | G8: 論壇 | J8: 新聞露出6篇 | K8: 20230704【國教行動聯盟新聞稿】
A9: 8 | B9: 2023 | C9: 2023/07/14 | D9: 肯定性平法修法方向 國教盟提醒仍須重視教育面、 基層學校需更多資源協助 | E9: 青少年性健康 | G9: 新聞稿 | J9: 新聞露出7篇 | K9: 20230714【國教行動聯盟新聞稿】
A10: 9 | B10: 2023 | C10: 2023/07/29 | D10: 肯定性別平等教育法三讀通過 國教盟提醒配套不足 呼籲對基層學校提供更多資源協助 | E10: 其他 | G10: 新聞稿 | I10: 有 | J10: 新聞露出5篇 | K10: 20230729【國教行動聯盟新聞稿】
A11: 10 | B11: 2023 | C11: 2023/08/22 | D11: 霸凌防制座談引發家長熱烈迴響 國教盟與橄欖枝中心、逆風劇團攜手防制校園霸凌 | E11: 校園安全 | G11: 座談會 | J11: 新聞露出4篇 | K11: 20230822【國教行動聯盟新聞稿】
A12: 11 | B12: 2023 | C12: 2023/08/31 | D12: 霸凌防制修法配套不足 預防及輔導才是重點 呼籲對學校提供法律資源、強化師生互動、建立學生互助網絡 | E12: 校園安全 | G12: 新聞稿 | J12: 新聞露出3篇 | K12: 20230831【國教行動聯盟新聞稿】
A13: 12 | B13: 2023 | C13: 2023/09/06 | D13: 加熱菸審查欠缺嚴格把關與本土研究 9.5萬青少年恐將成受害最大族群 | E13: 菸害防制 | G13: 新聞稿 | J13: 新聞露出11篇 | K13: 20230906【國教行動聯盟新聞稿】
A14: 13 | B14: 2023 | C14: 2023/10/23 | D14: 教育決定台灣未來！請問總統：許孩子什麼樣的未來？ 「2024年全國家長最關心的十大教育議題」問卷結果出爐！ 孩子的品格教育、校園安全、心理健康最被家長看重！ | E14: 校園安全 | F14: 心理健康 | G14: 新聞稿 | J14: 新聞露出24篇 | K14: 20231023【國教行動聯盟新聞稿】
A15: 14 | B15: 2023 | C15: 2023/11/13 | D15: 近四萬問卷九成三不同意大麻合法！ 民間團體呼籲落實反毒教育 釐清大麻迷思 | E15: 大麻防制 | G15: 新聞稿 | I15: 有 | J15: 新聞露出26篇 | K15: 20231113【國教行動聯盟新聞稿】
A16: 15 | B16: 2023 | C16: 2023/12/07 | D16: 推動友善校園、反霸凌、反歧視 應由增加輔導資源、落實品格與家庭教育做起 | E16: 校園安全 | G16: 新聞稿 | J16: 新聞露出5篇 | K16: 20231207【國教行動聯盟新聞稿】
A17: 16 | B17: 2023 | C17: 2023/12/11 | D17: 北一女教師罵課綱引關注 凸顯品格是教育重中之重 59教育團體14日邀總統候選人談教育理 | E17: 教育政策 | G17: 新聞稿 | I17: 有 | J17: 新聞露出21篇 | K17: 20231211【國教行動聯盟新聞稿】
A18: 17 | B18: 2023 | C18: 2023/12/27 | D18: 曝險少年輔導多頭馬車 校園攻擊並非偶然 國教盟呼籲檢討相關制度 | E18: 校園安全 | F18: 兒少保護 | G18: 新聞稿 | I18: 有 | J18: 新聞露出28篇 | K18: 20231227【國教行動聯盟新聞稿】
A19: 18 | B19: 2024 | C19: 2024/01/09 | D19: 補保護漏洞 和黑幫搶人 勿讓今日少年犯，成為明日成年犯！ 應確實檢討少保官未發揮效用、少輔會功能限縮問題 | E19: 兒少保護 | G19: 新聞稿 | I19: 有 | J19: 新聞露出24篇 | K19: 20240109【國教行動聯盟新聞稿】
A20: 19 | B20: 2024 | C20: 2024/01/11 | D20: 補校安漏洞 幫非行少年 預防少年殺人事件再度發生 應落實三級處遇輔導、中介教育、三級預防 | E20: 校園安全 | F20: 兒少保護 | G20: 新聞稿 | I20: 有 | J20: 新聞露出31篇 | K20: 20240111【國教行動聯盟新聞稿】
A21: 20 | B21: 2024 | C21: 2024/01/19 | D21: 少年犯罪日益嚴重 新北殺人事件並非偶然 國教盟呼籲檢討相關制度 | E21: 兒少保護 | G21: 新聞稿 | J21: 新聞露出26篇 | K21: 20240119【國教行動聯盟新聞稿】
A22: 21 | B22: 2024 | C22: 2024/02/03 | D22: 避免今日的非行少年，成為明日的成人罪犯親職教育 國教盟肯定教育部強化校園輔導管教與安檢措施 應落實家庭親職教育，校安輔導人力、中介教育、個管銜接仍待補足 | E22: 校園安全 | F22: 兒少保護 | G22: 新聞稿 | H22: 教育部 | I22: 有 | J22: 新聞露出13篇 | K22: 20240203【國教行動聯盟新聞稿】
A23: 22 | B23: 2024 | C23: 2024/02/24 | D23: 補社安漏洞 幫非行少年 預防少年殺人事件再度發生 建請司法院召集跨院協商會議 確實檢討少年事件處理 暨保護制度 | E23: 兒少保護 | G23: 新聞稿 | H23: 司法院 | I23: 有 | J23: 新聞露出22篇 | K23: 20240224【國教行動聯盟＆「孩想陪你長大」聯盟聯合新聞稿】
A24: 23 | B24: 2024 | C24: 2024/03/14 | D24: 家長再爆：菸商不怕罰 昨被稽查今繼續行銷加熱菸 家長團體：依法按次裁罰 每次5,000萬元! | E24: 菸害防制 | G24: 新聞稿 | J24: 新聞露出19篇 | K24: 20240314【國教行動聯盟與拒菸盟聯合新聞稿】
A25: 24 | B25: 2024 | C25: 2024/03/19 | D25: 回應立法院教文委員會昨日報告詢答： 少保官未見檢討 曝險少年定義狹隘 中介教育空中樓閣 是真心檢討還是虛晃一招？ | E25: 兒少保護 | G25: 新聞稿 | H25: 立法院 | I25: 有 | J25: 新聞露出11篇 | K25: 20240319【國教行動聯盟新聞稿】
A26: 25 | B26: 2024 | C26: 2024/04/10 | D26: 回顧410教改30週年 國教盟期盼深化教育對話 推動教育進 | E26: 教育政策 | G26: 新聞稿 | J26: 新聞露出15篇 | K26: 20240410【國教行動聯盟新聞稿】
A27: 26 | B27: 2024 | C27: 2024/04/12 | D27: 國教盟肯定新內閣教長人選 期盼推動教育精緻化 檢討教育缺失 共推教育進 | E27: 教育政策 | G27: 新聞稿 | H27: 行政院 | J27: 新聞露出11篇 | K27: 20240412【國教行動聯盟新聞稿】
A28: 27 | B28: 2024 | C28: 2024/04/17 | D28: 國教盟回應霸凌準則修正： 肯定教育部勇於面對問題 回應民間團體訴求 相關配套措施 應儘速啟動 | E28: 校園安全 | G28: 新聞稿 | H28: 教育部 | I28: 有 | J28: 新聞露出17篇 | K28: 20240417【國教行動聯盟新聞稿】
A29: 28 | B29: 2024 | C29: 2024/04/24 | D29: 補校安漏洞 幫非行少年 預防少年殺人事件再度發生 回應學生輔導法修法 國教盟提出三大訴求 | E29: 校園安全 | F29: 兒少保護 | G29: 新聞稿 | I29: 有 | J29: 新聞露出25篇 | K29: 20240424【國教行動聯盟新聞稿】
A30: 29 | B30: 2024 | C30: 2024/05/01 | D30: 回應國中小學生獎懲準則發布 國教盟提出三大疑慮 | E30: 校園安全 | G30: 新聞稿 | I30: 有 | J30: 新聞露出60篇 | K30: 20240501【國教行動聯盟新聞稿】
A31: 30 | B31: 2024 | C31: 2024/05/30 | D31: 回應鄭英耀部長提出課綱微調 國教盟表達對課綱三大訴求 | E31: 教育政策 | G31: 新聞稿 | I31: 有 | J31: 新聞露出33篇 | K31: 20240530【國教行動聯盟新聞稿】
A32: 31 | B32: 2024 | C32: 2024/06/06 | D32: 菸商要求速審開放加熱菸 ~目標鎖定百萬台灣年輕人 ?! 「減害」「避免黑市、走私」「損失菸捐 稅收」是誤導說法 台灣拒菸聯盟：衛福部職責是維護國人健康 應依法確實管控加熱菸！ | E32: 菸害防制 | G32: 新聞稿 | H32: 衛福部 | J32: 新聞露出20篇 | K32: 20240606【國教行動聯盟新聞稿】
A33: 32 | B33: 2024 | C33: 2024/06/14 | D33: 台灣需要什麼樣的性教育？ 家長本土化性教育問卷結果出爐！ 支持「全面性教育」應適當調整以符合本土需求 | E33: 青少年性健康 | G33: 新聞稿 | I33: 有 | J33: 新聞露出27篇 | K33: 20240614【國教行動聯盟新聞稿】
A34: 33 | B34: 2024 | C34: 2024/07/09 | D34: 補校安漏洞 幫非行少年 預防少年殺人事件再度發生 肯定學生輔導法修法符合期待 將有助防制校園霸凌、提升心理健康 | E34: 校園安全 | F34: 兒少保護 | G34: 新聞稿 | I34: 有 | J34: 新聞露出16篇 | K34: 20240709【國教行動聯盟新聞稿】
A35: 34 | B35: 2024 | C35: 2024/07/17 | D35: 電子煙氾濫是毒駕男撞死三重警背後主因 煙毒不分家 徹底禁絕電子煙才是根本之 | E35: 菸害防制 | G35: 新聞稿 | J35: 新聞露出6篇 | K35: 20240717【國教行動聯盟新聞稿】
A36: 35 | B36: 2024 | C36: 2024/08/30 | D36: 推翻前朝承諾？ 司法院、行政院少事會議決議迄未落實 國教盟呼籲應痛定思痛 不要讓下一個少年喪命 | E36: 其他 | G36: 新聞稿 | H36: 司法院、行政院 | I36: 有 | J36: 新聞露出15篇 | K36: 20240830【國教行動聯盟新聞稿】
A37: 36 | B37: 2024 | C37: 2024/09/06 | D37: AI使用疑慮風險高 切勿操之過及 教育部應先建立倫理規範 避免未蒙其利先受其害 | E37: 教育政策 | G37: 新聞稿 | H37: 教育部 | I37: 有 | J37: 新聞露出23篇 | K37: 20240906【國教行動聯盟新聞稿】
A38: 37 | B38: 2024 | C38: 2024/09/20 | D38: 新北割頸案凸顯少保調 查官角色衝突 人力長期不足 保護缺乏力度 國教盟呼籲:勿讓「假人權」保護傘成為犯罪溫床 | E38: 校園安全 | F38: 兒少保護 | G38: 新聞稿 | J38: 新聞露出14篇 | K38: 20240920【國教行動聯盟新聞稿】
A39: 38 | B39: 2024 | C39: 2024/09/24 | D39: 蠟瓶糖之亂 光下架不是解決之道 應建立完整的報關與查驗機制 並強化食安教育 保護兒少健康與消費權益 | E39: 青年參與 | G39: 新聞稿 | I39: 有 | J39: 新聞露出22篇 | K39: 20240924【國教行動聯盟青年部新聞稿】
A40: 39 | B40: 2024 | C40: 2024/09/27 | D40: 教師節教師不快樂，表單填寫成為教師噩夢 國教盟強烈要求：行政減量應有實際作為 | E40: 校園安全 | G40: 新聞稿 | I40: 有 | J40: 新聞露出8篇 | K40: 20240927【國教行動聯盟新聞稿】
...

Sheet 議題追蹤總覽
A1: 議題分類 | B1: 2023 | C1: 2024 | D1: 2025 | E1: 合計 | F1: 倡議現況 | G1: 下一步行動
A2: 兒少保護 | B2: =COUNTIFS(新聞稿資料庫!$E:$E,A2,新聞稿資料庫!$B:$B,"2023") -> 1 | C2: =COUNTIFS(新聞稿資料庫!$E:$E,A2,新聞稿資料庫!$B:$B,"2024") -> 6 | D2: =COUNTIFS(新聞稿資料庫!$E:$E,A2,新聞稿資料庫!$B:$B,"2025") -> 7 | E2: =SUM(B2:D2) -> 14
A3: 其他 | B3: =COUNTIFS(新聞稿資料庫!$E:$E,A3,新聞稿資料庫!$B:$B,"2023") -> 4 | C3: =COUNTIFS(新聞稿資料庫!$E:$E,A3,新聞稿資料庫!$B:$B,"2024") -> 3 | D3: =COUNTIFS(新聞稿資料庫!$E:$E,A3,新聞稿資料庫!$B:$B,"2025") -> 5 | E3: =SUM(B3:D3) -> 12
A4: 大麻防制 | B4: =COUNTIFS(新聞稿資料庫!$E:$E,A4,新聞稿資料庫!$B:$B,"2023") -> 2 | C4: =COUNTIFS(新聞稿資料庫!$E:$E,A4,新聞稿資料庫!$B:$B,"2024") -> 0 | D4: =COUNTIFS(新聞稿資料庫!$E:$E,A4,新聞稿資料庫!$B:$B,"2025") -> 0 | E4: =SUM(B4:D4) -> 2
A5: 心理健康 | B5: =COUNTIFS(新聞稿資料庫!$E:$E,A5,新聞稿資料庫!$B:$B,"2023") -> 0 | C5: =COUNTIFS(新聞稿資料庫!$E:$E,A5,新聞稿資料庫!$B:$B,"2024") -> 1 | D5: =COUNTIFS(新聞稿資料庫!$E:$E,A5,新聞稿資料庫!$B:$B,"2025") -> 9 | E5: =SUM(B5:D5) -> 10
A6: 教育政策 | B6: =COUNTIFS(新聞稿資料庫!$E:$E,A6,新聞稿資料庫!$B:$B,"2023") -> 1 | C6: =COUNTIFS(新聞稿資料庫!$E:$E,A6,新聞稿資料庫!$B:$B,"2024") -> 6 | D6: =COUNTIFS(新聞稿資料庫!$E:$E,A6,新聞稿資料庫!$B:$B,"2025") -> 6 | E6: =SUM(B6:D6) -> 13
A7: 早期療育 | B7: =COUNTIFS(新聞稿資料庫!$E:$E,A7,新聞稿資料庫!$B:$B,"2023") -> 0 | C7: =COUNTIFS(新聞稿資料庫!$E:$E,A7,新聞稿資料庫!$B:$B,"2024") -> 0 | D7: =COUNTIFS(新聞稿資料庫!$E:$E,A7,新聞稿資料庫!$B:$B,"2025") -> 1 | E7: =SUM(B7:D7) -> 1
A8: 校園安全 | B8: =COUNTIFS(新聞稿資料庫!$E:$E,A8,新聞稿資料庫!$B:$B,"2023") -> 7 | C8: =COUNTIFS(新聞稿資料庫!$E:$E,A8,新聞稿資料庫!$B:$B,"2024") -> 10 | D8: =COUNTIFS(新聞稿資料庫!$E:$E,A8,新聞稿資料庫!$B:$B,"2025") -> 4 | E8: =SUM(B8:D8) -> 21
A9: 菸害防制 | B9: =COUNTIFS(新聞稿資料庫!$E:$E,A9,新聞稿資料庫!$B:$B,"2023") -> 1 | C9: =COUNTIFS(新聞稿資料庫!$E:$E,A9,新聞稿資料庫!$B:$B,"2024") -> 8 | D9: =COUNTIFS(新聞稿資料庫!$E:$E,A9,新聞稿資料庫!$B:$B,"2025") -> 15 | E9: =SUM(B9:D9) -> 24
A10: 青少年性健康 | B10: =COUNTIFS(新聞稿資料庫!$E:$E,A10,新聞稿資料庫!$B:$B,"2023") -> 1 | C10: =COUNTIFS(新聞稿資料庫!$E:$E,A10,新聞稿資料庫!$B:$B,"2024") -> 2 | D10: =COUNTIFS(新聞稿資料庫!$E:$E,A10,新聞稿資料庫!$B:$B,"2025") -> 8 | E10: =SUM(B10:D10) -> 11
A11: 青年參與 | B11: =COUNTIFS(新聞稿資料庫!$E:$E,A11,新聞稿資料庫!$B:$B,"2023") -> 0 | C11: =COUNTIFS(新聞稿資料庫!$E:$E,A11,新聞稿資料庫!$B:$B,"2024") -> 3 | D11: =COUNTIFS(新聞稿資料庫!$E:$E,A11,新聞稿資料庫!$B:$B,"2025") -> 2 | E11: =SUM(B11:D11) -> 5
A12: 合計 | B12: =SUM(B2:B11) -> 17 | C12: =SUM(C2:C11) -> 39 | D12: =SUM(D2:D11) -> 57 | E12: =SUM(E2:E11) -> 113

Sheet 年度月度統計
A1: 月份 | B1: 2023 | C1: 2024 | D1: 2025 | E1: 合計
A2: 1月 | B2: =COUNTIFS(新聞稿資料庫!$B:$B,"2023",新聞稿資料庫!$C:$C,">="&DATE(2023,1,1),新聞稿資料庫!$C:$C,"<"&DATE(2023,1+1,1)) -> 0 | C2: =COUNTIFS(新聞稿資料庫!$B:$B,"2024",新聞稿資料庫!$C:$C,">="&DATE(2024,1,1),新聞稿資料庫!$C:$C,"<"&DATE(2024,1+1,1)) -> 0 | D2: =COUNTIFS(新聞稿資料庫!$B:$B,"2025",新聞稿資料庫!$C:$C,">="&DATE(2025,1,1),新聞稿資料庫!$C:$C,"<"&DATE(2025,1+1,1)) -> 0 | E2: =SUM(B2:D2) -> 0
A3: 2月 | B3: =COUNTIFS(新聞稿資料庫!$B:$B,"2023",新聞稿資料庫!$C:$C,">="&DATE(2023,2,1),新聞稿資料庫!$C:$C,"<"&DATE(2023,2+1,1)) -> 0 | C3: =COUNTIFS(新聞稿資料庫!$B:$B,"2024",新聞稿資料庫!$C:$C,">="&DATE(2024,2,1),新聞稿資料庫!$C:$C,"<"&DATE(2024,2+1,1)) -> 0 | D3: =COUNTIFS(新聞稿資料庫!$B:$B,"2025",新聞稿資料庫!$C:$C,">="&DATE(2025,2,1),新聞稿資料庫!$C:$C,"<"&DATE(2025,2+1,1)) -> 0 | E3: =SUM(B3:D3) -> 0
A4: 3月 | B4: =COUNTIFS(新聞稿資料庫!$B:$B,"2023",新聞稿資料庫!$C:$C,">="&DATE(2023,3,1),新聞稿資料庫!$C:$C,"<"&DATE(2023,3+1,1)) -> 0 | C4: =COUNTIFS(新聞稿資料庫!$B:$B,"2024",新聞稿資料庫!$C:$C,">="&DATE(2024,3,1),新聞稿資料庫!$C:$C,"<"&DATE(2024,3+1,1)) -> 0 | D4: =COUNTIFS(新聞稿資料庫!$B:$B,"2025",新聞稿資料庫!$C:$C,">="&DATE(2025,3,1),新聞稿資料庫!$C:$C,"<"&DATE(2025,3+1,1)) -> 0 | E4: =SUM(B4:D4) -> 0
A5: 4月 | B5: =COUNTIFS(新聞稿資料庫!$B:$B,"2023",新聞稿資料庫!$C:$C,">="&DATE(2023,4,1),新聞稿資料庫!$C:$C,"<"&DATE(2023,4+1,1)) -> 0 | C5: =COUNTIFS(新聞稿資料庫!$B:$B,"2024",新聞稿資料庫!$C:$C,">="&DATE(2024,4,1),新聞稿資料庫!$C:$C,"<"&DATE(2024,4+1,1)) -> 0 | D5: =COUNTIFS(新聞稿資料庫!$B:$B,"2025",新聞稿資料庫!$C:$C,">="&DATE(2025,4,1),新聞稿資料庫!$C:$C,"<"&DATE(2025,4+1,1)) -> 0 | E5: =SUM(B5:D5) -> 0
A6: 5月 | B6: =COUNTIFS(新聞稿資料庫!$B:$B,"2023",新聞稿資料庫!$C:$C,">="&DATE(2023,5,1),新聞稿資料庫!$C:$C,"<"&DATE(2023,5+1,1)) -> 0 | C6: =COUNTIFS(新聞稿資料庫!$B:$B,"2024",新聞稿資料庫!$C:$C,">="&DATE(2024,5,1),新聞稿資料庫!$C:$C,"<"&DATE(2024,5+1,1)) -> 0 | D6: =COUNTIFS(新聞稿資料庫!$B:$B,"2025",新聞稿資料庫!$C:$C,">="&DATE(2025,5,1),新聞稿資料庫!$C:$C,"<"&DATE(2025,5+1,1)) -> 0 | E6: =SUM(B6:D6) -> 0
A7: 6月 | B7: =COUNTIFS(新聞稿資料庫!$B:$B,"2023",新聞稿資料庫!$C:$C,">="&DATE(2023,6,1),新聞稿資料庫!$C:$C,"<"&DATE(2023,6+1,1)) -> 0 | C7: =COUNTIFS(新聞稿資料庫!$B:$B,"2024",新聞稿資料庫!$C:$C,">="&DATE(2024,6,1),新聞稿資料庫!$C:$C,"<"&DATE(2024,6+1,1)) -> 0 | D7: =COUNTIFS(新聞稿資料庫!$B:$B,"2025",新聞稿資料庫!$C:$C,">="&DATE(2025,6,1),新聞稿資料庫!$C:$C,"<"&DATE(2025,6+1,1)) -> 0 | E7: =SUM(B7:D7) -> 0
A8: 7月 | B8: =COUNTIFS(新聞稿資料庫!$B:$B,"2023",新聞稿資料庫!$C:$C,">="&DATE(2023,7,1),新聞稿資料庫!$C:$C,"<"&DATE(2023,7+1,1)) -> 0 | C8: =COUNTIFS(新聞稿資料庫!$B:$B,"2024",新聞稿資料庫!$C:$C,">="&DATE(2024,7,1),新聞稿資料庫!$C:$C,"<"&DATE(2024,7+1,1)) -> 0 | D8: =COUNTIFS(新聞稿資料庫!$B:$B,"2025",新聞稿資料庫!$C:$C,">="&DATE(2025,7,1),新聞稿資料庫!$C:$C,"<"&DATE(2025,7+1,1)) -> 0 | E8: =SUM(B8:D8) -> 0
A9: 8月 | B9: =COUNTIFS(新聞稿資料庫!$B:$B,"2023",新聞稿資料庫!$C:$C,">="&DATE(2023,8,1),新聞稿資料庫!$C:$C,"<"&DATE(2023,8+1,1)) -> 0 | C9: =COUNTIFS(新聞稿資料庫!$B:$B,"2024",新聞稿資料庫!$C:$C,">="&DATE(2024,8,1),新聞稿資料庫!$C:$C,"<"&DATE(2024,8+1,1)) -> 0 | D9: =COUNTIFS(新聞稿資料庫!$B:$B,"2025",新聞稿資料庫!$C:$C,">="&DATE(2025,8,1),新聞稿資料庫!$C:$C,"<"&DATE(2025,8+1,1)) -> 0 | E9: =SUM(B9:D9) -> 0
A10: 9月 | B10: =COUNTIFS(新聞稿資料庫!$B:$B,"2023",新聞稿資料庫!$C:$C,">="&DATE(2023,9,1),新聞稿資料庫!$C:$C,"<"&DATE(2023,9+1,1)) -> 0 | C10: =COUNTIFS(新聞稿資料庫!$B:$B,"2024",新聞稿資料庫!$C:$C,">="&DATE(2024,9,1),新聞稿資料庫!$C:$C,"<"&DATE(2024,9+1,1)) -> 0 | D10: =COUNTIFS(新聞稿資料庫!$B:$B,"2025",新聞稿資料庫!$C:$C,">="&DATE(2025,9,1),新聞稿資料庫!$C:$C,"<"&DATE(2025,9+1,1)) -> 0 | E10: =SUM(B10:D10) -> 0
A11: 10月 | B11: =COUNTIFS(新聞稿資料庫!$B:$B,"2023",新聞稿資料庫!$C:$C,">="&DATE(2023,10,1),新聞稿資料庫!$C:$C,"<"&DATE(2023,10+1,1)) -> 0 | C11: =COUNTIFS(新聞稿資料庫!$B:$B,"2024",新聞稿資料庫!$C:$C,">="&DATE(2024,10,1),新聞稿資料庫!$C:$C,"<"&DATE(2024,10+1,1)) -> 0 | D11: =COUNTIFS(新聞稿資料庫!$B:$B,"2025",新聞稿資料庫!$C:$C,">="&DATE(2025,10,1),新聞稿資料庫!$C:$C,"<"&DATE(2025,10+1,1)) -> 0 | E11: =SUM(B11:D11) -> 0
A12: 11月 | B12: =COUNTIFS(新聞稿資料庫!$B:$B,"2023",新聞稿資料庫!$C:$C,">="&DATE(2023,11,1),新聞稿資料庫!$C:$C,"<"&DATE(2023,11+1,1)) -> 0 | C12: =COUNTIFS(新聞稿資料庫!$B:$B,"2024",新聞稿資料庫!$C:$C,">="&DATE(2024,11,1),新聞稿資料庫!$C:$C,"<"&DATE(2024,11+1,1)) -> 0 | D12: =COUNTIFS(新聞稿資料庫!$B:$B,"2025",新聞稿資料庫!$C:$C,">="&DATE(2025,11,1),新聞稿資料庫!$C:$C,"<"&DATE(2025,11+1,1)) -> 0 | E12: =SUM(B12:D12) -> 0
A13: 12月 | B13: =COUNTIFS(新聞稿資料庫!$B:$B,"2023",新聞稿資料庫!$C:$C,">="&DATE(2023,12,1),新聞稿資料庫!$C:$C,"<"&DATE(2023,12+1,1)) -> 0 | C13: =COUNTIFS(新聞稿資料庫!$B:$B,"2024",新聞稿資料庫!$C:$C,">="&DATE(2024,12,1),新聞稿資料庫!$C:$C,"<"&DATE(2024,12+1,1)) -> 0 | D13: =COUNTIFS(新聞稿資料庫!$B:$B,"2025",新聞稿資料庫!$C:$C,">="&DATE(2025,12,1),新聞稿資料庫!$C:$C,"<"&DATE(2025,12+1,1)) -> 0 | E13: =SUM(B13:D13) -> 0
A14: 合計 | B14: =SUM(B2:B13) -> 0 | C14: =SUM(C2:C13) -> 0 | D14: =SUM(D2:D13) -> 0 | E14: =SUM(E2:E13) -> 0
