Workbook

Sheet 新聞稿資料庫
A1: 編號 | B1: 年度 | C1: 日期 | D1: 標題 | E1: 議題分類 | F1: 次要議題 | G1: 行動類型 | H1: 訴求對象 | I1: 政府回應 | J1: 檔案名
A2: 2 | B2: 2024 | C2: 2024/00/00 | D2: 1101221+跨院際「少年事件政策協商平台會議」新聞稿 | E2: 校園安全 | G2: 新聞稿 | I2: 有 | J2: 1101221+跨院際「少年事件政策協商平台會議」新聞稿.docx
A3: 3 | B3: 2024 | C3: 2024/01/09 | D3: 國教行動聯盟「補保護漏洞 和黑幫搶人 不讓少年殺人事件再度發生」新聞稿 | E3: 校園安全 | F3: 兒少保護 | G3: 記者會 | I3: 有 | J3: 20240109：國教行動聯盟「補保護漏洞 和黑幫搶人 不讓少年殺人事件再度發生」新聞稿.docx
A4: 4 | B4: 2024 | C4: 2024/01/19 | D4: 國教行動聯盟「少年犯罪日益嚴重 新北殺人事件並非偶然」記者會新聞稿 | E4: 校園安全 | G4: 記者會 | I4: 有 | J4: 20240119：國教行動聯盟「少年犯罪日益嚴重 新北殺人事件並非偶然」記者會新聞稿.docx
A5: 5 | B5: 2024 | C5: 2024/03/19 | D5: 國教行動聯盟「少保官未見檢討 曝險少年定義狹隘 中介教育空中樓閣 是真心檢 | E5: 校園安全 | F5: 兒少保護 | G5: 新聞稿 | I5: 有 | J5: 20240319：國教行動聯盟「少保官未見檢討 曝險少年定義狹隘 中介教育空中樓閣 是真心檢.docx
A6: 6 | B6: 2024 | C6: 2024/04/17 | D6: 新聞稿：國教盟回應霸凌準則修正：肯定教育部勇於面對問題 回應民間團體訴求 積 | E6: 校園安全 | G6: 新聞稿 | I6: 有 | J6: 20240417新聞稿：國教盟回應霸凌準則修正：肯定教育部勇於面對問題 回應民間團體訴求 積.docx
A7: 7 | B7: 2024 | C7: 2024/04/24 | D7: 新聞稿：回應學生輔導法修法 國教盟提出三大訴求 | E7: 校園安全 | F7: 心理健康 | G7: 新聞稿 | I7: 有 | J7: 20240424新聞稿：回應學生輔導法修法 國教盟提出三大訴求.docx
A8: 8 | B8: 2024 | C8: 2024/07/09 | D8: 國教行動聯盟新聞稿「國教盟肯定學生輔導法修法符合期待 預期將有助學生心理健 | E8: 校園安全 | F8: 心理健康 | G8: 新聞稿 | I8: 有 | J8: 20240709國教行動聯盟新聞稿「國教盟肯定學生輔導法修法符合期待 預期將有助學生心理健.docx
A9: 9 | B9: 2024 | C9: 2024/08/30 | D9: 國教行動聯盟「建請確實檢討少年事件處理暨保護制度」記者會新聞稿 | E9: 校園安全 | G9: 記者會 | I9: 有 | J9: 20240830國教行動聯盟「建請確實檢討少年事件處理暨保護制度」記者會新聞稿.docx
A10: 11 | B10: 2024 | C10: 2024/09/20 | D10: 國教行動聯盟「新北割頸案凸顯少保調查官角色衝突」記者會新聞稿 | E10: 校園安全 | F10: 兒少保護 | G10: 記者會 | I10: 有 | J10: 20240920國教行動聯盟「新北割頸案凸顯少保調查官角色衝突」記者會新聞稿.docx
A11: 12 | B11: 2024 | C11: 2024/09/30 | D11: 國教行動聯盟「悲劇不是意外，系統早已失靈！ 」陳情行動記者會新聞稿 | E11: 校園安全 | G11: 記者會 | I11: 有 | J11: 20240930國教行動聯盟「悲劇不是意外，系統早已失靈！ 」陳情行動記者會新聞稿.docx
A12: 14 | B12: 2025 | C12: 2025/01/02 | D12: 落實「健康台灣」願景 保障兒童健康未來 | E12: 教育政策 | G12: 陳情 | H12: 教育部、衛福部、行政院 | I12: 有 | J12: 20250102_「全國教育團體聯合呼籲應重新啟動生生喝國產乳計畫.docx
A13: 15 | B13: 2025 | C13: 2025/01/09 | D13: 公聽會家長聲音缺席，如何落實兒童最佳利益？ | E13: 兒少保護 | G13: 公聽會 | H13: 立法院 | I13: 有 | J13: 20250109_公聽會家長聲音缺席如何落實兒童最佳利益.docx
A14: 16 | B14: 2025 | C14: 2025/01/10 | D14: 菸防法修法兩週年 台灣加熱菸、加味菸管制陷入困境！ | E14: 菸害防制 | G14: 記者會 | H14: 衛福部、國健署、立法院 | J14: 20250110_菸防法修法兩週年台灣加熱菸、加味菸管制陷入困境.docx
A15: 17 | B15: 2025 | C15: 2025/01/13 | D15: 青少年每10萬人有50.34人感染 12年來淋病暴增七倍 | E15: 青少年性健康 | G15: 新聞稿 | H15: 衛福部 | I15: 有 | J15: 20250113_青少年每10萬人有50.34人感染 12年來淋病暴.docx
A16: 19 | B16: 2025 | C16: 2025/01/15 | D16: 青少女梅毒病例10年增長53倍，性病低齡化問題浮現 | E16: 青少年性健康 | G16: 公聽會 | H16: 教育部、衛福部、立法院 | I16: 有 | J16: 20250115_青少女梅毒成長53倍.docx
A17: 20 | B17: 2025 | C17: 2025/01/17 | D17: 小學三年級染性病是怎麼回事？ | E17: 青少年性健康 | G17: 新聞稿 | H17: 教育部、衛福部 | I17: 有 | J17: 20250117_小學三年級染性病是怎麼回事.docx
A18: 21 | B18: 2025 | C18: 2025/01/20 | D18: 台灣性教育學會、華人情感教育發展協會、國教行動聯盟 | E18: 青少年性健康 | G18: 新聞稿 | H18: 衛福部、立法院 | J18: 20250120_2024台灣十大性與情感教育新聞事件.docx
A19: 22 | B19: 2025 | C19: 2025/01/21 | D19: 全台首次！8743份問卷揭示「這世代的心聲」! | E19: 校園安全 | F19: 青年參與 | G19: 新聞稿 | J19: 20250121_全台首次8743份問卷揭示這世代的心聲.docx
A20: 23 | B20: 2025 | C20: 2025/01/21 | D20: 全台首次！？「2025臺灣青少年最關心的十大議題」震撼揭曉———改變，從傾聽開始 | E20: 青年參與 | G20: 記者會 | J20: 20250121_青少年最關心的十大議題.docx
A21: 24 | B21: 2025 | C21: 2025/01/26 | D21: 年節出國帶加熱菸回台 自用送禮代購都違法 | E21: 菸害防制 | G21: 新聞稿 | J21: 20250126_年節出國帶加熱菸回台_自用送禮代購都違法.docx
A22: 25 | B22: 2025 | C22: 2025/02/13 | D22: 徒法不足以自行 兒少權法修法恐適得其反？ | E22: 兒少保護 | G22: 公聽會 | H22: 法務部、立法院 | J22: 20250213_徒法不足以自行兒少權法修法恐適得其反.docx
A23: 26 | B23: 2025 | C23: 2025/02/20 | D23: 兒少權修法應具體回應青少年需求 | E23: 菸害防制 | F23: 青少年性健康 | G23: 公聽會 | H23: 教育部、立法院 | I23: 有 | J23: 20250220_兒少權修法應具體回應青少年需求.docx
A24: 27 | B24: 2025 | C24: 2025/03/06 | D24: 電子煙修法仍存漏洞 校園喪屍煙彈難擋 | E24: 菸害防制 | G24: 新聞稿 | H24: 衛福部、行政院 | J24: 20250306_電子煙修法仍存漏洞校園喪屍煙彈難擋.docx
A25: 28 | B25: 2025 | C25: 2025/03/07 | D25: 「青少女梅毒成長53倍、淋病暴增7倍，政府還想開放事後避孕藥？」 | E25: 青少年性健康 | G25: 新聞稿 | H25: 衛福部 | I25: 有 | J25: 20250307_青少女梅毒成長53倍、淋病暴增7倍政府還想開放.docx
A26: 29 | B26: 2025 | C26: 2025/03/07 | D26: 會後照片及資料：https://reurl.cc/RerXgG | E26: 菸害防制 | G26: 新聞稿 | H26: 衛福部、國健署、行政院 | J26: 20250307_台灣拒菸聯盟.docx
A27: 30 | B27: 2025 | C27: 2025/03/17 | D27: 情緒障礙飆升41%！國教盟籲校園手機使用聚焦內容管理、培養學生數位韌性 | E27: 校園安全 | F27: 心理健康 | G27: 新聞稿 | H27: 教育部、衛福部、行政院 | I27: 有 | J27: 20250317_情緒障礙飆升41%國教盟籲校園手機使用聚焦內容管.docx
A28: 31 | B28: 2025 | C28: 2025/03/24 | D28: 早療通報再創新高 療育量能遠遠不足 | E28: 早期療育 | G28: 新聞稿 | H28: 衛福部 | I28: 有 | J28: 20250324_早療通報再創新高療育量能遠遠不足.docx
A29: 32 | B29: 2025 | C29: 2025/04/23 | D29: 「423嬰兒 兒童 青少年 精神衛生日」 | E29: 心理健康 | G29: 新聞稿 | H29: 教育部、衛福部、國健署 | I29: 有 | J29: 20250423_423嬰兒 兒童 青少年 精神健康日」國教行動聯盟.docx
A30: 33 | B30: 2025 | C30: 2025/04/24 | D30: 青少年說：我們不想再被毒駕撞傷！ | E30: 菸害防制 | F30: 校園安全 | G30: 新聞稿 | H30: 衛福部、立法院 | I30: 有 | J30: 20250424_青年部康橋事件.docx
A31: 34 | B31: 2025 | C31: 2025/04/30 | D31: 『看見不同，孩子的未來不是病名』 | E31: 心理健康 | G31: 新聞稿 | H31: 教育部、衛福部、立法院 | I31: 有 | J31: 20250430_看見不同孩子的未來不是病名.docx
A32: 35 | B32: 2025 | C32: 2025/04/30 | D32: 青少年說：我們不想再被毒駕撞傷！ | E32: 菸害防制 | F32: 校園安全 | G32: 新聞稿 | H32: 衛福部、立法院 | J32: 20250430_看見孩子不同的需要.docx
A33: 36 | B33: 2025 | C33: 2025/05/14 | D33: 共同跨域網絡守護青少年身心與數位健康 | E33: 教育政策 | G33: 新聞稿 | H33: 教育部 | J33: 20250514_共同跨域網絡守護青少年身心與數位健康.docx
A34: 37 | B34: 2025 | C34: 2025/05/22 | D34: 92%民意怒吼、每年20幼童枉死！國教盟揭8,700份調查 籲修法『終身監禁不得假釋＋強制治療』 | E34: 兒少保護 | F34: 心理健康 | G34: 新聞稿 | H34: 立法院 | I34: 有 | J34: 20250522_兒虐修法終身監禁不得假釋.docx
A35: 38 | B35: 2025 | C35: 2025/05/26 | D35: 世界無菸日 青年行動劇揭露「菸商最常用的3大行銷伎倆」! | E35: 菸害防制 | F35: 青年參與 | G35: 記者會 | H35: 國健署 | J35: 20250526_世界無菸日青年行動劇揭露菸商最常用的3大行銷伎.docx
A36: 39 | B36: 2025 | C36: 2025/05/29 | D36: 健康促進學校邊緣化性健康 造成青少年性病飆升 | E36: 青少年性健康 | G36: 新聞稿 | H36: 教育部、衛福部 | I36: 有 | J36: 20250529_健康促進學校邊緣化性健康_正式版.docx
A37: 40 | B37: 2025 | C37: 2025/06/02 | D37: 國際七國專家齊聚聚焦毒品危機 | E37: 菸害防制 | F37: 心理健康 | G37: 新聞稿 | H37: 教育部 | I37: 有 | J37: 20250602_國際七國專家齊聚聚焦毒品危機.docx
A38: 41 | B38: 2025 | C38: 2025/06/03 | D38: 七國專家聚焦毒品危機 大麻與依托咪酯威脅台灣青少年 | E38: 菸害防制 | G38: 新聞稿 | H38: 教育部 | J38: 20250603_七國專家聚焦毒品危機大麻與依托咪酯威脅台灣青少年.docx
A39: 42 | B39: 2025 | C39: 2025/06/05 | D39: 學習歷程採計不該成為考驗信任的軍備競賽！ | E39: 教育政策 | G39: 新聞稿 | H39: 教育部、立法院 | I39: 有 | J39: 20250605_學習歷程採計不該成為軍備競賽.docx
A40: 43 | B40: 2025 | C40: 2025/06/21 | D40: 2025台灣青少年神經多樣性生活導師國際研討會登場 從理解到實踐，創造台灣在地的青少年神經多樣性支持制度 | E40: 心理健康 | G40: 論壇 | I40: 有 | J40: 20250621_台灣青少年神經多樣性國際研討會.docx
...

Sheet 議題追蹤總覽
A1: 議題 | B1: 2024年 | C1: 2025年 | D1: 合計 | E1: 倡議現況 | F1: 下一步行動
A2: 菸害防制 | B2: =COUNTIFS(新聞稿資料庫!E2:E66,A2,新聞稿資料庫!B2:B66,"2024") -> 0 | C2: =COUNTIFS(新聞稿資料庫!E2:E66,A2,新聞稿資料庫!B2:B66,"2025") -> 17 | D2: =SUM(B2:C2) -> 17
A3: 校園安全 | B3: =COUNTIFS(新聞稿資料庫!E2:E66,A3,新聞稿資料庫!B2:B66,"2024") -> 10 | C3: =COUNTIFS(新聞稿資料庫!E2:E66,A3,新聞稿資料庫!B2:B66,"2025") -> 7 | D3: =SUM(B3:C3) -> 17
A4: 青少年性健康 | B4: =COUNTIFS(新聞稿資料庫!E2:E66,A4,新聞稿資料庫!B2:B66,"2024") -> 0 | C4: =COUNTIFS(新聞稿資料庫!E2:E66,A4,新聞稿資料庫!B2:B66,"2025") -> 10 | D4: =SUM(B4:C4) -> 10
A5: 兒少保護 | B5: =COUNTIFS(新聞稿資料庫!E2:E66,A5,新聞稿資料庫!B2:B66,"2024") -> 0 | C5: =COUNTIFS(新聞稿資料庫!E2:E66,A5,新聞稿資料庫!B2:B66,"2025") -> 6 | D5: =SUM(B5:C5) -> 6
A6: 心理健康 | B6: =COUNTIFS(新聞稿資料庫!E2:E66,A6,新聞稿資料庫!B2:B66,"2024") -> 0 | C6: =COUNTIFS(新聞稿資料庫!E2:E66,A6,新聞稿資料庫!B2:B66,"2025") -> 6 | D6: =SUM(B6:C6) -> 6
A7: 教育政策 | B7: =COUNTIFS(新聞稿資料庫!E2:E66,A7,新聞稿資料庫!B2:B66,"2024") -> 0 | C7: =COUNTIFS(新聞稿資料庫!E2:E66,A7,新聞稿資料庫!B2:B66,"2025") -> 4 | D7: =SUM(B7:C7) -> 4
A8: 青年參與 | B8: =COUNTIFS(新聞稿資料庫!E2:E66,A8,新聞稿資料庫!B2:B66,"2024") -> 0 | C8: =COUNTIFS(新聞稿資料庫!E2:E66,A8,新聞稿資料庫!B2:B66,"2025") -> 3 | D8: =SUM(B8:C8) -> 3
A9: 大麻防制 | B9: =COUNTIFS(新聞稿資料庫!E2:E66,A9,新聞稿資料庫!B2:B66,"2024") -> 0 | C9: =COUNTIFS(新聞稿資料庫!E2:E66,A9,新聞稿資料庫!B2:B66,"2025") -> 0 | D9: =SUM(B9:C9) -> 0
A10: 人工生殖 | B10: =COUNTIFS(新聞稿資料庫!E2:E66,A10,新聞稿資料庫!B2:B66,"2024") -> 0 | C10: =COUNTIFS(新聞稿資料庫!E2:E66,A10,新聞稿資料庫!B2:B66,"2025") -> 0 | D10: =SUM(B10:C10) -> 0
A11: 早期療育 | B11: =COUNTIFS(新聞稿資料庫!E2:E66,A11,新聞稿資料庫!B2:B66,"2024") -> 0 | C11: =COUNTIFS(新聞稿資料庫!E2:E66,A11,新聞稿資料庫!B2:B66,"2025") -> 1 | D11: =SUM(B11:C11) -> 1
A12: 其他 | B12: =COUNTIFS(新聞稿資料庫!E2:E66,A12,新聞稿資料庫!B2:B66,"2024") -> 0 | C12: =COUNTIFS(新聞稿資料庫!E2:E66,A12,新聞稿資料庫!B2:B66,"2025") -> 1 | D12: =SUM(B12:C12) -> 1
A13: 合計 | B13: =SUM(B2:B12) -> 10 | C13: =SUM(C2:C12) -> 55 | D13: =SUM(D2:D12) -> 65

Sheet 年度月度統計
A1: 月份 | B1: 2024年 | C1: 2025年 | D1: 合計
A2: 1月 | B2: =COUNTIFS(新聞稿資料庫!B2:B66,"2024",新聞稿資料庫!C2:C66,"2024/01/*") -> 2 | C2: =COUNTIFS(新聞稿資料庫!B2:B66,"2025",新聞稿資料庫!C2:C66,"2025/01/*") -> 10 | D2: =SUM(B2:C2) -> 12
A3: 2月 | B3: =COUNTIFS(新聞稿資料庫!B2:B66,"2024",新聞稿資料庫!C2:C66,"2024/02/*") -> 0 | C3: =COUNTIFS(新聞稿資料庫!B2:B66,"2025",新聞稿資料庫!C2:C66,"2025/02/*") -> 2 | D3: =SUM(B3:C3) -> 2
A4: 3月 | B4: =COUNTIFS(新聞稿資料庫!B2:B66,"2024",新聞稿資料庫!C2:C66,"2024/03/*") -> 1 | C4: =COUNTIFS(新聞稿資料庫!B2:B66,"2025",新聞稿資料庫!C2:C66,"2025/03/*") -> 5 | D4: =SUM(B4:C4) -> 6
A5: 4月 | B5: =COUNTIFS(新聞稿資料庫!B2:B66,"2024",新聞稿資料庫!C2:C66,"2024/04/*") -> 2 | C5: =COUNTIFS(新聞稿資料庫!B2:B66,"2025",新聞稿資料庫!C2:C66,"2025/04/*") -> 4 | D5: =SUM(B5:C5) -> 6
A6: 5月 | B6: =COUNTIFS(新聞稿資料庫!B2:B66,"2024",新聞稿資料庫!C2:C66,"2024/05/*") -> 0 | C6: =COUNTIFS(新聞稿資料庫!B2:B66,"2025",新聞稿資料庫!C2:C66,"2025/05/*") -> 4 | D6: =SUM(B6:C6) -> 4
A7: 6月 | B7: =COUNTIFS(新聞稿資料庫!B2:B66,"2024",新聞稿資料庫!C2:C66,"2024/06/*") -> 0 | C7: =COUNTIFS(新聞稿資料庫!B2:B66,"2025",新聞稿資料庫!C2:C66,"2025/06/*") -> 4 | D7: =SUM(B7:C7) -> 4
A8: 7月 | B8: =COUNTIFS(新聞稿資料庫!B2:B66,"2024",新聞稿資料庫!C2:C66,"2024/07/*") -> 1 | C8: =COUNTIFS(新聞稿資料庫!B2:B66,"2025",新聞稿資料庫!C2:C66,"2025/07/*") -> 3 | D8: =SUM(B8:C8) -> 4
A9: 8月 | B9: =COUNTIFS(新聞稿資料庫!B2:B66,"2024",新聞稿資料庫!C2:C66,"2024/08/*") -> 1 | C9: =COUNTIFS(新聞稿資料庫!B2:B66,"2025",新聞稿資料庫!C2:C66,"2025/08/*") -> 4 | D9: =SUM(B9:C9) -> 5
A10: 9月 | B10: =COUNTIFS(新聞稿資料庫!B2:B66,"2024",新聞稿資料庫!C2:C66,"2024/09/*") -> 2 | C10: =COUNTIFS(新聞稿資料庫!B2:B66,"2025",新聞稿資料庫!C2:C66,"2025/09/*") -> 2 | D10: =SUM(B10:C10) -> 4
A11: 10月 | B11: =COUNTIFS(新聞稿資料庫!B2:B66,"2024",新聞稿資料庫!C2:C66,"2024/10/*") -> 0 | C11: =COUNTIFS(新聞稿資料庫!B2:B66,"2025",新聞稿資料庫!C2:C66,"2025/10/*") -> 6 | D11: =SUM(B11:C11) -> 6
A12: 11月 | B12: =COUNTIFS(新聞稿資料庫!B2:B66,"2024",新聞稿資料庫!C2:C66,"2024/11/*") -> 0 | C12: =COUNTIFS(新聞稿資料庫!B2:B66,"2025",新聞稿資料庫!C2:C66,"2025/11/*") -> 4 | D12: =SUM(B12:C12) -> 4
A13: 12月 | B13: =COUNTIFS(新聞稿資料庫!B2:B66,"2024",新聞稿資料庫!C2:C66,"2024/12/*") -> 0 | C13: =COUNTIFS(新聞稿資料庫!B2:B66,"2025",新聞稿資料庫!C2:C66,"2025/12/*") -> 7 | D13: =SUM(B13:C13) -> 7
A14: 合計 | B14: =SUM(B2:B13) -> 9 | C14: =SUM(C2:C13) -> 55 | D14: =SUM(D2:D13) -> 64
